<?xml version="1.0" ?>
<robot name="differential_drive_robot" xmlns:xacro="http://ros.org/wiki/xacro">
    <material name="dark_grey">
        <color rgba="0.2 0.2 0.2 1.0"/>
    </material>
    <material name="light_grey">
        <color rgba="0.4 0.4 0.4 1.0"/>
    </material>
    <material name="yellow">
        <color rgba="0.8 0.8 0.0 1.0"/>
    </material>
    <material name="black">
        <color rgba="0.15 0.15 0.15 1.0"/>
    </material>
    <material name="aluminum">
        <color rgba="0.8 0.85 0.88 1"/>
    </material>
    <material name="white">
        <color rgba="1.0 1.0 1.0 1.0"/>
    </material>

    <xacro:property name="wheel_link_length" value="0.2" /> 
    <xacro:property name="wheel_link_radius" value="0.215" /> 

    <!-- Body Dimensions -->
    <xacro:property name="body_link_x_dim" value="1.0"/>
    <xacro:property name="body_link_y_dim" value="1.0"/>
    <xacro:property name="body_link_z_dim" value="0.5"/>
    <xacro:property name="wheel_link_z_location" value="0"/>
    <xacro:property name="body_mass" value="300"/>

    <xacro:property name="pi_constant" value="3.1415926"/>
    <xacro:property name="wheel_mass" value="10"/>

    <!-- Moments -->
    <xacro:property name="Iz_wheel" value="${0.5 * wheel_mass * wheel_link_radius * wheel_link_radius}"/>
    <xacro:property name="Ixy_wheel" value="${(1.0)/(12.0)*wheel_mass * (3.0 * wheel_link_radius * wheel_link_radius + wheel_link_length * wheel_link_length)}"/>

    <xacro:property name="wheel_weight" value="3.0" />
    <xacro:property name="wheel_radius" value="0.215" />
    <xacro:property name="wheel_width" value="0.14" />

    <xacro:property name="mu1" value="1.0" />
    <xacro:property name="mu2" value="1.0" />

    <xacro:macro name="inertia_wheel">
        <inertial>
            <origin xyz = "0 0 0" rpy="0 0 0"/>
            <mass value="${wheel_mass}"/>
            <inertia ixx="${Ixy_wheel}"  iyy="${Ixy_wheel}"  izz="${Iz_wheel}" ixy="0.0" ixz="0.0" iyz="0.0"/>
        </inertial>
    </xacro:macro>

    <xacro:include filename="$(find amiga_description)/urdf/amiga.gazebo"/>

    <!-- define the base link -->
    <link name="dummy"/>
    <joint name="dummy_joint" type="fixed">
        <parent link="dummy"/>
        <child link="body_link"/>
    </joint>

    <link name="body_link">
        <visual>
            <origin xyz="0 0 0" rpy="0 0 0" />
            <geometry>
                <mesh filename="package://amiga_description/meshes/amiga_base.stl" scale="1 1 1" />
                <!-- <mesh filename="package://amiga_description/meshes/amiga_base.stl" scale="0.001 0.001 0.001" /> -->
            </geometry>
        </visual>
        <collision>
            <origin xyz="0 0 0" rpy="0 0 0" />
            <geometry>
                <mesh filename="package://amiga_description/meshes/amiga_base.stl" scale="1 1 1" />
                <!-- <mesh filename="package://amiga_description/meshes/amiga_base.stl" scale="0.001 0.001 0.001" /> -->
            </geometry>
        </collision>
        <inertial>
            <origin xyz="0 0 0.4" rpy="0 0 0" />
            <mass value="335.0"/>
            <inertia    ixx="94.59"
                        iyy="94.03"
                        izz="171.3"
                        ixy="0.001581"
                        ixz="-0.02401"
                        iyz="0.003946"/>
        </inertial>
    </link>

    <xacro:macro name="wheel" params="prefix *joint_pose">
        <joint name="wheel${prefix}_joint" type="continuous">
            <parent link="body_link"/>
            <child link="wheel${prefix}_link"/>
            <xacro:insert_block name="joint_pose"/>
            <axis xyz="0 0 -1"/>
            <limit effort="1000" velocity="1000"/>
            <dynamic damping="1.0" friction="1.0"/>
        </joint>
        <link name="wheel${prefix}_link">
            <visual>
                <origin xyz="0 0.395 0" rpy="0 0 0" />
                <geometry>
                    <mesh filename="package://amiga_description/meshes/smartfork_tire.stl" scale="0.001 0.001 0.001" />
                </geometry>
            </visual>
            <collision>
                <origin xyz="0 0 0" rpy="0 0 0" />
                <geometry>
                    <cylinder radius="${wheel_radius}" length="${wheel_width}"/>
                </geometry>
            </collision>
            <xacro:inertia_wheel/>
        </link>
        <gazebo reference = "wheel${prefix}_link">
            <mu1>${mu1}</mu1>
            <mu2>${mu1}</mu2>
            <kp value="10000000.0" />
            <kd value="1" />
            <fdir1 value="1 0 0"/>
            <material>Gazebo/Gray</material>
        </gazebo>
        <transmission name="${prefix}_wheel_trans">
            <type>transmission_interface/SimpleTransmission</type>
            <joint name="wheel${prefix}_joint">
                <hardwareInterface>hardware_interface/EffortJointInterface</hardwareInterface>
            </joint>
            <actuator name="${prefix}_actuator">
                <mechanicalReduction>1</mechanicalReduction>
            </actuator>
        </transmission>
    </xacro:macro>
    <xacro:wheel prefix="1">
        <origin xyz="0.5 0.49 0.22" rpy="1.5708 0 0" />
    </xacro:wheel>
    <xacro:wheel prefix="3">
        <origin xyz="-0.5 0.49 0.22" rpy="1.5708 0 0" />
    </xacro:wheel>
    <xacro:wheel prefix="2">
        <origin xyz="0.5 -0.51 0.22" rpy="1.5708 0 0" />
    </xacro:wheel>
    <xacro:wheel prefix="4">
        <origin xyz="-0.5 -0.51 0.22" rpy="1.5708 0 0" />
    </xacro:wheel>

    <link name="imu_link">
        <inertial>
            <mass value="0.001"/>
            <origin rpy="0 0 0" xyz="0 0 0"/>
            <inertia ixx="1e-09" ixy="0.0" ixz="0.0" iyy="1e-09" iyz="0.0" izz="1e-09"/>
        </inertial>
    </link>
    <joint name="imu_joint" type="fixed">
        <parent link="body_link"/>
        <child link="imu_link"/>
    </joint>


    <!-- Add GPS simulation library -->
    <link name="navsat_link">
        <visual>
            <geometry>
                <cylinder length="0.016" radius="0.026"/>
            </geometry>
            <origin xyz="0 0 0.008"/>
            <material name="black"/>
        </visual>
    </link>
    <joint name="navsat_joint" type="fixed">
        <parent link="body_link"/>
        <child link="navsat_link"/>
        <origin xyz="0.5 0.0 0.6"/>
    </joint>


</robot>