<?xml version="1.0" ?>
<robot name="robot_with_wheels">
    <material name="dark_grey">
        <color rgba="  0.2 0.2 0.2 1.0"/>
    </material>
    <material name="light_grey">
        <color rgba="0.4 0.4 0.4 1.0"/>
    </material>
    <material name="yellow">
        <color rgba="0.8 0.8 0.0 1.0"/>
    </material>
    <material name="black">
        <color rgba="0.15 0.15 0.15 1.0"/>
    </material>
    <material name="aluminum">
    <color rgba="0.8 0.85 0.88 1"/> <!-- Adjust the RGBA values as needed -->
    </material>

    <material name="white">
        <color rgba="1.0 1.0 1.0 1.0"/>
    </material>

    <link name="base_link"/>
    <joint name="base_link_joint" type="fixed">
        <origin rpy="0 0 0" xyz="0 0 0"/>
        <parent link="base_link"/>
        <child link="chassis_link"/>
    </joint>

    <link name="chassis_link" />
    <!-- Define origin for the front_center frame -->
    <joint name="world_joint" type="fixed">
        <origin xyz="0 0.0 0.65" rpy="0 0 0" />
        <parent link="chassis_link" />
        <child link="front_center" />
    </joint>
    <link name="front_center" />
    <!-- Define origin for the front_center frame -->
    <joint name="front_center_joint" type="fixed">
        <origin xyz="0 -1.0 0" rpy="1.5708 0 0" />
        <parent link="front_center" />
        <child link="smartfork3" />
    </joint>
    <link name="wheel3">
        <visual>
            <origin xyz="0 0.395 0" rpy="0 0 0" />
            <material name="dark_grey"/>
            <geometry>
                <mesh filename="package://amiga_ros/amiga_description/smartfork_tire.stl" scale="0.001 0.001 0.001" />
            </geometry>
        </visual>
        <collision>
            <origin xyz="0 0.395 0" rpy="0 0 0" />
            <geometry>
                <mesh filename="package://amiga_ros/amiga_description/smartfork_tire.stl" scale="0.001 0.001 0.001" />
            </geometry>
        </collision>
        <inertial>
            <mass value="15" />
            <origin xyz="0 0 0" rpy="0 0 0" />
            <inertia ixx="0.03" iyy="0.03" izz="0.03" ixy="0.0" ixz="0.0" iyz="0.0" />
        </inertial>
    </link>
    <gazebo reference="wheel3">
        <material>Gazebo/DarkGrey</material>
        <selfCollide>false</selfCollide>
        <mu1 value="0.5" />
        <mu2 value="0.5" />
        <kp value="10000000.0" />
        <kd value="1" />
        <fdir1 value="1 0 0" />
        <plugin name="gazebo_ros_control">
            <robotNamespace>/</robotNamespace>
        </plugin>
    </gazebo>
    <link name="smartfork3">
        <visual>
            <material name="white"/>
            <geometry>
                <mesh filename="package://amiga_ros/amiga_description/smartfork.stl" scale="0.001 0.001 0.001" />
            </geometry>
        </visual>
        <collision>
            <geometry>
                <mesh filename="package://amiga_ros/amiga_description/smartfork.stl" scale="0.001 0.001 0.001" />
            </geometry>
        </collision>
        <inertial>
            <mass value="40" />
            <origin xyz="0 0 0" rpy="0 0 0" />
            <inertia ixx="0.03" iyy="0.03" izz="0.03" ixy="0.0" ixz="0.0" iyz="0.0" />
        </inertial>
    </link>
    <joint name="wheel_2_joint" type="continuous">
        <parent link="smartfork3" />
        <child link="wheel3" />
        <origin xyz="0 -0.395 0" rpy="0 0 0" />
        <axis xyz="0 0 -1" />
    </joint>
    <!-- <transmission name="front_right_wheel_trans">
        <type>transmission_interface/SimpleTransmission</type>
        <joint name="wheel_2_joint">
            <hardwareInterface>transmission_interface/VelocityJointInterface</hardwareInterface>
        </joint>
        <actuator name="front_right_actuator">
            <mechanicalReduction>1</mechanicalReduction>
            <hardwareInterface>transmission_interface/VelocityJointInterface</hardwareInterface>
        </actuator>
    </transmission> -->
    <!-- <transmission name="front_right_wheel_trans" type="SimpleTransmission">
    <actuator name="front_right_actuator"/>
    <joint name="wheel_2_joint"/>
    <mechanicalReduction>1</mechanicalReduction>
    <motorTorqueConstant>1</motorTorqueConstant>
    </transmission> -->
    <link name="rig_34_left">
        <visual>
            <geometry>
                <box size="1.2 0.04 0.03" />
            </geometry>
            <origin rpy="1.5708 0.0 0.0" xyz="-0.5 0 0" />
            <material name="aluminum"/>
        </visual>
        <collision>
            <geometry>
                <box size="1.2 0.04 0.03" />
            </geometry>
            <origin rpy="1.5708 0.0 0.0" xyz="-0.5 0 0" />
        </collision>
        <inertial>
            <mass value="0.1" />
            <origin xyz="0 0 0" rpy="0 0 0" />
            <inertia ixx="0.03" iyy="0.03" izz="0.03" ixy="0.0" ixz="0.0" iyz="0.0" />
        </inertial>
    </link>
    <link name="rig_34_right">
        <visual>
            <geometry>
                <box size="1.2 0.04 0.03" />
            </geometry>
            <origin rpy="1.5708 0.0 0.0" xyz="-0.5 0 0" />
            <material name="aluminum"/>
        </visual>
        <collision>
            <geometry>
                <box size="1.2 0.04 0.03" />
            </geometry>
            <origin rpy="1.5708 0.0 0.0" xyz="-0.5 0 0" />
        </collision>
        <inertial>
            <mass value="0.1" />
            <origin xyz="0 0 0" rpy="0 0 0" />
            <inertia ixx="0.03" iyy="0.03" izz="0.03" ixy="0.0" ixz="0.0" iyz="0.0" />
        </inertial>
    </link>
    <joint name="rig34_right" type="fixed">
        <parent link="smartfork3" />
        <child link="rig_34_left" />
        <origin xyz="0 -0.03 0.06" rpy="-1.5708 0 0" />
    </joint>
    <joint name="rig34_left" type="fixed">
        <parent link="smartfork3" />
        <child link="rig_34_right" />
        <origin xyz="0 -0.03 -0.06" rpy="-1.5708 0 0" />
    </joint>
    <link name="wheel4">
        <visual>
            <origin xyz="0 0.395 0" rpy="0 0 0" />
            <material name="dark_grey"/>
            <geometry>
                <mesh filename="package://amiga_ros/amiga_description/smartfork_tire.stl" scale="0.001 0.001 0.001" />
            </geometry>
        </visual>
        <collision>
            <origin xyz="0 0.395 0" rpy="0 0 0" />
            <geometry>
                <mesh filename="package://amiga_ros/amiga_description/smartfork_tire.stl" scale="0.001 0.001 0.001" />
            </geometry>
        </collision>
        <inertial>
            <mass value="15" />
            <origin xyz="0 0 0" rpy="0 0 0" />
            <inertia ixx="0.03" iyy="0.03" izz="0.03" ixy="0.0" ixz="0.0" iyz="0.0" />
        </inertial>
    </link>
    <gazebo reference="wheel4">
        <material>Gazebo/DarkGrey</material>
        <selfCollide>false</selfCollide>
        <mu1 value="0.5" />
        <mu2 value="0.5" />
        <kp value="10000000.0" />
        <kd value="1" />
        <fdir1 value="1 0 0" />
    </gazebo>
    <link name="smartfork4">
        <visual>
            <material name="white"/>
            <geometry>
                <mesh filename="package://amiga_ros/amiga_description/smartfork.stl" scale="0.001 0.001 0.001" />
            </geometry>
        </visual>
        <collision>
            <geometry>
                <mesh filename="package://amiga_ros/amiga_description/smartfork.stl" scale="0.001 0.001 0.001" />
            </geometry>
        </collision>
        <inertial>
            <mass value="40" />
            <origin xyz="0 0 0" rpy="0 0 0" />
            <inertia ixx="0.03" iyy="0.03" izz="0.03" ixy="0.0" ixz="0.0" iyz="0.0" />
        </inertial>
    </link>
    <joint name="smartfork_34" type="fixed">
        <origin xyz="-1.0 0 0" rpy="0 0 0" />
        <parent link="smartfork3" />
        <child link="smartfork4" />
    </joint>
    <joint name="wheel_3_joint" type="continuous">
        <parent link="smartfork4" />
        <child link="wheel4" />
        <origin xyz="0 -0.395 0" rpy="0 0 0" />
        <axis xyz="0 0 -1" />
    </joint>
    <!-- In reality, Jackal has only two motors, one per side. However, it's more
        straightforward for Gazebo to simulate as if there's an actuator per wheel. -->
    <!-- <transmission name="rear_right_wheel_trans">
        <type>transmission_interface/SimpleTransmission</type>
        <joint name="wheel_3_joint">
            <hardwareInterface>transmission_interface/VelocityJointInterface</hardwareInterface>
        </joint>
        <actuator name="rear_right_actuator">
            <mechanicalReduction>1</mechanicalReduction>
            <hardwareInterface>transmission_interface/VelocityJointInterface</hardwareInterface>
        </actuator>
    </transmission> -->
    <!--     
    <transmission name="rear_right_wheel_trans" type="SimpleTransmission">
    <actuator name="rear_right_actuator"/>
    <joint name="wheel_3_joint"/>
    <mechanicalReduction>1</mechanicalReduction>
    <motorTorqueConstant>1</motorTorqueConstant>
    </transmission> -->
    <link name="link3_connector">
        <visual>
            <geometry>
                <mesh filename="package://amiga_ros/amiga_description/connector.stl" />
            </geometry>
            <origin rpy="0 0 0" xyz="0 0 -0.01" />
        </visual>
        <collision>
            <geometry>
                <mesh filename="package://amiga_ros/amiga_description/connector.stl" />
            </geometry>
            <origin rpy="0 0 0" xyz="0 0 -0.01" />
        </collision>
        <inertial>
            <mass value="0.1" />
            <origin xyz="0 0 0" rpy="0 0 0" />
            <inertia ixx="0.03" iyy="0.03" izz="0.03" ixy="0.0" ixz="0.0" iyz="0.0" />
        </inertial>
    </link>
    <joint name="link3_connector_joint" type="fixed">
        <parent link="smartfork3" />
        <child link="link3_connector" />
        <origin xyz="0 0 0" rpy="0 0 0" />
    </joint>
    <link name="rig_13">
        <visual>
            <geometry>
                <box size="0.04 0.02 2.0" />
            </geometry>
            <origin rpy="0 0.0 0.0" xyz="0 0.02 0" />
            <material name="aluminum"/>
        </visual>
        <collision>
            <geometry>
                <box size="0.04 0.02 2.0" />
            </geometry>
            <origin rpy="0 0.0 0.0" xyz="0 0.02 0" />
        </collision>
        <inertial>
            <mass value="0.1" />
            <origin xyz="0 0 0" rpy="0 0 0" />
            <inertia ixx="0.03" iyy="0.03" izz="0.03" ixy="0.0" ixz="0.0" iyz="0.0" />
        </inertial>
    </link>
    <joint name="rig_13_joint" type="fixed">
        <parent link="link3_connector" />
        <child link="rig_13" />
        <origin xyz="0 0 -1.0" rpy="0 0 0" />
    </joint>
    <link name="link4_connector">
        <visual>
            <geometry>
                <mesh filename="package://amiga_ros/amiga_description/connector.stl" />
            </geometry>
            <origin rpy="0 0 0" xyz="0 0 -0.01" />
        </visual>
        <collision>
            <geometry>
                <mesh filename="package://amiga_ros/amiga_description/connector.stl" />
            </geometry>
            <origin rpy="0 0 0" xyz="0 0 -0.01" />
        </collision>
        <inertial>
            <mass value="0.1" />
            <origin xyz="0 0 0" rpy="0 0 0" />
            <inertia ixx="0.03" iyy="0.03" izz="0.03" ixy="0.0" ixz="0.0" iyz="0.0" />
        </inertial>
    </link>
    <joint name="link4_connector_joint" type="fixed">
        <parent link="smartfork4" />
        <child link="link4_connector" />
        <origin xyz="0 0 0" rpy="0 0 0" />
    </joint>
    <link name="rig_24">
        <visual>
            <geometry>
                <box size="0.04 0.02 2.0" />
            </geometry>
            <origin rpy="0 0.0 0.0" xyz="0 0.02 0" />
            <material name="aluminum"/>
        </visual>
        <collision>
            <geometry>
                <box size="0.04 0.02 2.0" />
            </geometry>
            <origin rpy="0 0.0 0.0" xyz="0 0.02 0" />
        </collision>
        <inertial>
            <mass value="0.1" />
            <origin xyz="0 0 0" rpy="0 0 0" />
            <inertia ixx="0.03" iyy="0.03" izz="0.03" ixy="0.0" ixz="0.0" iyz="0.0" />
        </inertial>
    </link>
    <joint name="rig_24_joint" type="fixed">
        <parent link="link4_connector" />
        <child link="rig_24" />
        <origin xyz="0 0 -1.0" rpy="0 0 0" />
    </joint>
    <link name="smartfork1">
        <visual>
            <material name="white"/>
            <geometry>
                <mesh filename="package://amiga_ros/amiga_description/smartfork.stl" scale="0.001 0.001 0.001" />
            </geometry>
            <origin xyz="0 0 0" rpy="0 3.1415926 0" />
        </visual>
        <collision>
            <geometry>
                <mesh filename="package://amiga_ros/amiga_description/smartfork.stl" scale="0.001 0.001 0.001" />
            </geometry>
            <origin xyz="0 0 0" rpy="0 3.1415926 0" />
        </collision>
        <inertial>
            <mass value="40" />
            <origin xyz="0 0 0" rpy="0 0 0" />
            <inertia ixx="0.03" iyy="0.03" izz="0.03" ixy="0.0" ixz="0.0" iyz="0.0" />
        </inertial>
    </link>
    <joint name="world_joint_fork1" type="fixed">
        <origin xyz="0 1.0 0" rpy="1.5708 0 0" />
        <parent link="front_center" />
        <child link="smartfork1" />
    </joint>
    <!-- wheel 1 -->
    <link name="wheel1">
        <visual>
            <origin xyz="0 0.395 0" rpy="0 0 0" />
            <material name="dark_grey"/>
            <geometry>
                <mesh filename="package://amiga_ros/amiga_description/smartfork_tire.stl" scale="0.001 0.001 0.001" />
            </geometry>
        </visual>
        <collision>
            <origin xyz="0 0.395 0" rpy="0 0 0" />
            <geometry>
                <mesh filename="package://amiga_ros/amiga_description/smartfork_tire.stl" scale="0.001 0.001 0.001" />
            </geometry>
        </collision>
        <inertial>
            <mass value="15" />
            <origin xyz="0 0 0" rpy="0 0 0" />
            <inertia ixx="0.03" iyy="0.03" izz="0.03" ixy="0.0" ixz="0.0" iyz="0.0" />
        </inertial>
    </link>
    <gazebo reference="wheel1">
        <material>Gazebo/DarkGrey</material>
        <selfCollide>false</selfCollide>
        <mu1 value="0.5" />
        <mu2 value="0.5" />
        <kp value="10000000.0" />
        <kd value="1" />
        <fdir1 value="1 0 0" />
    </gazebo>
    <joint name="wheel_0_joint" type="continuous">
        <parent link="smartfork1" />
        <child link="wheel1" />
        <origin xyz="0 -0.395 0" rpy="0 0 0" />
        <axis xyz="0 0 -1" />
    </joint>
    <!-- In reality, Jackal has only two motors, one per side. However, it's more
        straightforward for Gazebo to simulate as if there's an actuator per wheel. -->
    <!-- <transmission name="front_left_wheel_trans">
        <type>transmission_interface/SimpleTransmission</type>
        <joint name="wheel_0_joint">
            <hardwareInterface>transmission_interface/VelocityJointInterface</hardwareInterface>
        </joint>
        <actuator name="front_left_actuator">
            <mechanicalReduction>1</mechanicalReduction>
            <hardwareInterface>transmission_interface/VelocityJointInterface</hardwareInterface>
        </actuator>
    </transmission> -->
    <!-- <transmission name="front_left_wheel_trans" type="SimpleTransmission">
    <actuator name="front_left_actuator"/>
        <joint name="wheel_0_joint">
            <hardwareInterface>transmission_interface/VelocityJointInterface</hardwareInterface>
        </joint>      
        <mechanicalReduction>1</mechanicalReduction>
    <motorTorqueConstant>1</motorTorqueConstant>
    </transmission> -->
    <link name="smartfork2">
        <visual>
        <material name="white"/>
            <geometry>
                <mesh filename="package://amiga_ros/amiga_description/smartfork.stl" scale="0.001 0.001 0.001" />
            </geometry>
            <origin xyz="0 0 0" rpy="0 3.1415926 0" />
        </visual>
        <collision>
            <geometry>
                <mesh filename="package://amiga_ros/amiga_description/smartfork.stl" scale="0.001 0.001 0.001" />
            </geometry>
            <origin xyz="0 0 0" rpy="0 3.1415926 0" />
        </collision>
        <inertial>
            <mass value="40" />
            <origin xyz="0 0 0" rpy="0 0 0" />
            <inertia ixx="0.03" iyy="0.03" izz="0.03" ixy="0.0" ixz="0.0" iyz="0.0" />
        </inertial>
    </link>
    <joint name="smartfork_12" type="fixed">
        <origin xyz="-1.0 0.0 0.0" rpy="0 0 0" />
        <parent link="smartfork1" />
        <child link="smartfork2" />
    </joint>
    <!-- wheel 1 -->
    <link name="wheel2">
        <visual>
            <origin xyz="0 0.395 0" rpy="0 0 0" />
            <material name="dark_grey"/>
            <geometry>
                <mesh filename="package://amiga_ros/amiga_description/smartfork_tire.stl" scale="0.001 0.001 0.001" />
            </geometry>
        </visual>
        <collision>
            <origin xyz="0 0.395 0" rpy="0 0 0" />
            <geometry>
                <mesh filename="package://amiga_ros/amiga_description/smartfork_tire.stl" scale="0.001 0.001 0.001" />
            </geometry>
        </collision>
        <inertial>
            <mass value="15" />
            <origin xyz="0 0 0" rpy="0 0 0" />
            <inertia ixx="0.03" iyy="0.03" izz="0.03" ixy="0.0" ixz="0.0" iyz="0.0" />
        </inertial>
    </link>
    <gazebo reference="wheel2">
        <material>Gazebo/DarkGrey</material>
        <selfCollide>false</selfCollide>
        <mu1 value="0.5" />
        <mu2 value="0.5" />
        <kp value="10000000.0" />
        <kd value="1" />
        <fdir1 value="1 0 0" />
    </gazebo>
    <joint name="wheel_1_joint" type="continuous">
        <parent link="smartfork2" />
        <child link="wheel2" />
        <origin xyz="0 -0.395 0" rpy="0 0 0" />
        <axis xyz="0 0 -1" />
    </joint>
    <!-- <transmission name="rear_left_wheel_trans">
        <type>transmission_interface/SimpleTransmission</type>
        <joint name="wheel_1_joint">
            <hardwareInterface>transmission_interface/VelocityJointInterface</hardwareInterface>
        </joint>
        <actuator name="rear_left_actuator">
            <mechanicalReduction>1</mechanicalReduction>
            <hardwareInterface>transmission_interface/VelocityJointInterface</hardwareInterface>
        </actuator>
    </transmission> -->
    <!-- <transmission name="rear_left_wheel_trans" type="SimpleTransmission">
    <actuator name="rear_left_actuator"/>
    <joint name="wheel_1_joint"/>
    <mechanicalReduction>1</mechanicalReduction>
    <motorTorqueConstant>1</motorTorqueConstant>
    </transmission> -->
    <link name="link1_connector">
        <visual>
            <geometry>
                <mesh filename="package://amiga_ros/amiga_description/connector.stl" />
            </geometry>
            <origin rpy="0 0 0" xyz="0 0 -0.01" />
        </visual>
        <collision>
            <geometry>
                <mesh filename="package://amiga_ros/amiga_description/connector.stl" />
            </geometry>
            <origin rpy="0 0 0" xyz="0 0 -0.01" />
        </collision>
        <inertial>
            <mass value="0.1" />
            <origin xyz="0 0 0" rpy="0 0 0" />
            <inertia ixx="0.03" iyy="0.03" izz="0.03" ixy="0.0" ixz="0.0" iyz="0.0" />
        </inertial>
    </link>
    <joint name="link1_connector_joint" type="fixed">
        <parent link="smartfork1" />
        <child link="link1_connector" />
        <origin xyz="0 0 0" rpy="0 0 0" />
    </joint>
    <link name="link2_connector">
        <visual>
            <geometry>
                <mesh filename="package://amiga_ros/amiga_description/connector.stl" />
            </geometry>
            <origin rpy="0 0 0" xyz="0 0 -0.01" />
        </visual>
        <collision>
            <geometry>
                <mesh filename="package://amiga_ros/amiga_description/connector.stl" />
            </geometry>
            <origin rpy="0 0 0" xyz="0 0 -0.01" />
        </collision>
        <inertial>
            <mass value="0.1" />
            <origin xyz="0 0 0" rpy="0 0 0" />
            <inertia ixx="0.03" iyy="0.03" izz="0.03" ixy="0.0" ixz="0.0" iyz="0.0" />
        </inertial>
    </link>
    <joint name="link2_connector_joint" type="fixed">
        <parent link="smartfork2" />
        <child link="link2_connector" />
        <origin xyz="0 0 0" rpy="0 0 0" />
    </joint>
    <link name="rig_12_left">
        <visual>
            <geometry>
                <box size="1.2 0.04 0.03" />
            </geometry>
            <origin rpy="1.5708 0.0 0.0" xyz="-0.5 0 0" />
            <material name="aluminum"/>
        </visual>
        <collision>
            <geometry>
                <box size="1.2 0.04 0.03" />
            </geometry>
            <origin rpy="1.5708 0.0 0.0" xyz="-0.5 0 0" />
        </collision>
        <inertial>
            <mass value="0.1" />
            <origin xyz="0 0 0" rpy="0 0 0" />
            <inertia ixx="0.03" iyy="0.03" izz="0.03" ixy="0.0" ixz="0.0" iyz="0.0" />
        </inertial>
    </link>
    <link name="rig_12_right">
        <visual>
            <geometry>
                <box size="1.2 0.04 0.03" />
            </geometry>
            <origin rpy="1.5708 0.0 0.0" xyz="-0.5 0 0" />
            <material name="aluminum"/>
        </visual>
        <collision>
            <geometry>
                <box size="1.2 0.04 0.03" />
            </geometry>
            <origin rpy="1.5708 0.0 0.0" xyz="-0.5 0 0" />
        </collision>
        <inertial>
            <mass value="0.1" />
            <origin xyz="0 0 0" rpy="0 0 0" />
            <inertia ixx="0.03" iyy="0.03" izz="0.03" ixy="0.0" ixz="0.0" iyz="0.0" />
        </inertial>
    </link>
    <joint name="rig12_right" type="fixed">
        <parent link="smartfork1" />
        <child link="rig_12_left" />
        <origin xyz="0 -0.03 0.06" rpy="-1.5708 0 0" />
    </joint>
    <joint name="rig12_left" type="fixed">
        <parent link="smartfork1" />
        <child link="rig_12_right" />
        <origin xyz="0 -0.03 -0.06" rpy="-1.5708 0 0" />
    </joint>
    <gazebo>
        <plugin name="gazebo_ros_control" filename="libgazebo_ros_control.so">
            <robotNamespace>/</robotNamespace>
        </plugin>
    </gazebo>
    <transmission name="trans_wheel_2_joint">
        <type>transmission_interface/SimpleTransmission</type>
        <joint name="wheel_2_joint">
            <hardwareInterface>hardware_interface/VelocityJointInterface</hardwareInterface>
        </joint>
        <actuator name="wheel_2_joint_motor">
            <hardwareInterface>hardware_interface/VelocityJointInterface</hardwareInterface>
            <mechanicalReduction>1</mechanicalReduction>
        </actuator>
    </transmission>
    <transmission name="trans_wheel_3_joint">
        <type>transmission_interface/SimpleTransmission</type>
        <joint name="wheel_3_joint">
            <hardwareInterface>hardware_interface/VelocityJointInterface</hardwareInterface>
        </joint>
        <actuator name="wheel_3_joint_motor">
            <hardwareInterface>hardware_interface/VelocityJointInterface</hardwareInterface>
            <mechanicalReduction>1</mechanicalReduction>
        </actuator>
    </transmission>
    <transmission name="trans_wheel_0_joint">
        <type>transmission_interface/SimpleTransmission</type>
        <joint name="wheel_0_joint">
            <hardwareInterface>hardware_interface/VelocityJointInterface</hardwareInterface>
        </joint>
        <actuator name="wheel_0_joint_motor">
            <hardwareInterface>hardware_interface/VelocityJointInterface</hardwareInterface>
            <mechanicalReduction>1</mechanicalReduction>
        </actuator>
    </transmission>
    <transmission name="trans_wheel_1_joint">
        <type>transmission_interface/SimpleTransmission</type>
        <joint name="wheel_1_joint">
            <hardwareInterface>hardware_interface/VelocityJointInterface</hardwareInterface>
        </joint>
        <actuator name="wheel_1_joint_motor">
            <hardwareInterface>hardware_interface/VelocityJointInterface</hardwareInterface>
            <mechanicalReduction>1</mechanicalReduction>
        </actuator>
    </transmission>

    <!-- Add the Laser Scanner -->
    <link name="front_laser">
        <inertial>
            <mass value="1.1"/>
            <origin xyz="0 0 0"/>
            <inertia ixx="0.00307156543804" ixy="0.0" ixz="0.0" iyy="0.0031284904152700005" iyz="0.0" izz="0.00196432421427"  />
        </inertial>
        <visual>
            <origin rpy="0 0 0" xyz="0 0 0"/>
            <geometry>
                <!-- Origin of this mesh is the focal point of the LIDAR. -->
                <mesh filename="package://lms1xx/meshes/sick-lms1xx.dae"/>
            </geometry>
        </visual>
        <collision>
            <origin rpy="0 0 0" xyz="  0 0 -0.05"/>
            <geometry>
                <box size="0.105 0.1 0.1"/>
            </geometry>
        </collision>    
    </link>

    <gazebo reference="front_laser">
        <turnGravityOff>true</turnGravityOff>
        <sensor name="front_laser" type="ray">
        <pose>0 0 0 0 0 0</pose>
        <visualize>false</visualize>
        <update_rate>50</update_rate>
        <ray>
            <scan>
                <horizontal>
                    <samples>720</samples>

                    <resolution>1</resolution>
                    <min_angle>-2.35619</min_angle>

                    <max_angle>2.35619</max_angle>
                </horizontal>
            </scan>

            <range>
                <min>0.1</min>
                <max>30.0</max>
                <resolution>0.01</resolution>
            </range>
            <noise>
                <type>gaussian</type>
                <mean>0.0</mean>
                <stddev>0.001</stddev>
            </noise>
        </ray>
            <plugin filename="libgazebo_ros_laser.so" name="gazebo_ros_laser"  >
                <topicName>front/scan</topicName>
                <frameName>front_laser</frameName>
                <robotNamespace>/</robotNamespace>
            </plugin>
        </sensor>
    </gazebo>
    
    <joint name="front_laser_mount_joint" type="fixed">
        <origin rpy="0 0 0" xyz="0 0 0.03"/>
        <parent link="front_center"/>
        <child link="front_laser_mount"/>
    </joint>

    <link name="front_laser_mount">
        <visual>
        <origin rpy="0 0 0" xyz="0 0 0"/>
        <geometry>
            <!-- Origin of this mesh is the base of the bracket. -->
            <mesh filename="package://jackal_description/meshes/sick-lms1xx-upright-bracket.stl"/>
        </geometry>
        <material name="dark_grey"/>
        </visual>
    </link>
    <joint name="front_laser_joint" type="fixed">
        <!-- This offset is from the base of the bracket to the LIDAR's focal point. -->
        <origin rpy="0 0 0" xyz="0 0 0.149"/>
        <parent link="front_laser_mount"/>
        <child link="front_laser"/>
    </joint>
    <gazebo reference="front_laser_mount"  >
        <material>Gazebo/DarkGrey</material>
    </gazebo>

    <!-- Add the Velodyne HDL-16 -->
    <link name="velodyne">
      <inertial>
        <mass value="0.01"/>
        <origin xyz="0 0 0"/>
        <inertia ixx="1e-7" ixy="0" ixz="0" iyy="1e-7" iyz="0" izz="1e-7"/>
      </inertial>
      <visual>
        <origin xyz="0 0 -0.0377" />
        <geometry>
          <mesh filename="package://velodyne_description/meshes/VLP16_scan.dae" />
        </geometry>
      </visual>
      <collision>
        <geometry>
          <sphere radius="0"/>
        </geometry>
      </collision>
    </link>
    <joint name="velodyne_joint" type="fixed">
        <origin rpy="0 0 0" xyz="0 0 0.25"/>
        <parent link="front_center"/>
        <child link="velodyne"/>
    </joint>
    <gazebo reference="velodyne">
        <turnGravityOff>true</turnGravityOff>
        <sensor name="velodyne" type="ray">
        <pose>0 0 0 0 0 0</pose>
        <visualize>false</visualize>
        <update_rate>10</update_rate>
        <ray>
            <scan>
                <horizontal>
                    <samples>1875</samples>
                    <resolution>1</resolution>
                    <min_angle>-3.14159</min_angle>
                    <max_angle>3.14159</max_angle>
                </horizontal>
                <vertical>
                    <samples>16</samples>
                    <resolution>1</resolution>
                    <min_angle>-0.26179938333</min_angle>
                    <max_angle>0.26179938333</max_angle>
                </vertical>
            </scan>
            <range>
                <min>0.3</min>
                <max>131</max>
                <resolution>0.001</resolution>
            </range>
            <noise>
              <type>gaussian</type>
              <mean>0.0</mean>
              <stddev>0.0</stddev>
            </noise>
        </ray>
          <plugin name="gazebo_ros_laser_controller" filename="libgazebo_ros_velodyne_laser.so">
            <topicName>/velodyne_points</topicName>
            <frameName>velodyne</frameName>
            <organize_cloud>false</organize_cloud>
            <min_range>0.9</min_range>
            <max_range>130.0</max_range>
            <gaussianNoise>0.008</gaussianNoise>
          </plugin>
        </sensor>
    </gazebo>

    <!-- Add IMU Link and simulation library  -->
    <link name="imu_link">
        <inertial>
            <mass value="0.001"/>
            <origin rpy="0 0 0" xyz="0 0 0"/>
            <inertia ixx="1e-09" ixy="0.0" ixz="0.0" iyy="1e-09" iyz="0.0" izz="1e-09"/>
        </inertial>
    </link>
    <joint name="imu_joint" type="fixed">
        <parent link="front_center"/>
        <child link="imu_link"/>
    </joint>
    <gazebo>
        <plugin filename="libhector_gazebo_ros_imu.so" name="imu_controller">
            <robotNamespace>/</robotNamespace>
            <updateRate>50.0</updateRate>
            <bodyName>imu_link</bodyName>
            <topicName>imu/data</topicName>
            <accelDrift>0.005 0.005 0.005</accelDrift>
            <accelGaussianNoise>0.005 0.005 0.005</accelGaussianNoise>
            <rateDrift>0.005 0.005 0.005 </rateDrift>
            <rateGaussianNoise>0.005 0.005 0.005 </rateGaussianNoise>
            <headingDrift>0.005</headingDrift>
            <headingGaussianNoise>0.005</headingGaussianNoise>
        </plugin>
    </gazebo>
    <!-- Add GPS simulation library -->
    <link name="navsat_link">
        <visual>
        <geometry>
            <cylinder length="0.016" radius="0.026"/>
        </geometry>
        <origin xyz="0 0 0.008"/>
        <material name="black"/>
        </visual>
    </link>
    <joint name="navsat_joint" type="fixed">
        <parent link="front_center"/>
        <child link="navsat_link"/>
        <origin xyz="0 0.2 0.036"/>
    </joint>
    <gazebo reference="navsat_link">
        <material>Gazebo/DarkGrey</material>
        <turnGravityOff>false</turnGravityOff>
    </gazebo>
    <gazebo>
        <plugin filename="libhector_gazebo_ros_gps.so" name="gps_controller">
            <updateRate>40</updateRate>
            <robotNamespace>/</robotNamespace>
            <bodyName>navsat_link</bodyName>
            <frameId>front_center</frameId>
            <topicName>/navsat/fix</topicName>
            <velocityTopicName>/navsat/vel</velocityTopicName>
            <referenceLatitude>49.9</referenceLatitude>
            <referenceLongitude>8.9</referenceLongitude>
            <referenceHeading>90</referenceHeading>
            <referenceAltitude>0</referenceAltitude>
            <drift>0.0001 0.0001 0.0001</drift>
        </plugin>
    </gazebo>


</robot>

